2025-04-24 20:07:58,660 - error_test - INFO - 成功导入通信模块
2025-04-24 20:07:58,662 - error_test - INFO - 成功导入PLC模拟器
2025-04-24 20:07:58,662 - error_test - INFO - ====== 开始测试通信模块错误处理 ======
2025-04-24 20:07:58,662 - error_test - INFO - === 测试连接错误处理 ===
2025-04-24 20:07:58,662 - error_test - INFO - 测试不存在的端口...
2025-04-24 20:07:58,663 - modbus_client - INFO - 尝试连接到串口 NONEXISTENT，波特率 9600
2025-04-24 20:07:58,663 - pymodbus.client.sync - ERROR - could not open port 'NONEXISTENT': FileNotFoundError(2, '系统找不到指定的文件。', None, 2)
2025-04-24 20:07:58,664 - modbus_client - ERROR - 无法连接到PLC，端口: NONEXISTENT
2025-04-24 20:07:58,664 - error_test - INFO - 不存在端口测试通过
2025-04-24 20:07:58,700 - error_test - INFO - 测试错误的通信参数...
2025-04-24 20:07:58,700 - modbus_client - INFO - 尝试连接到串口 COM1，波特率 115200
2025-04-24 20:07:58,700 - modbus_client - ERROR - 连接PLC时发生错误: Not a valid parity: 'Z'
2025-04-24 20:07:58,707 - error_test - INFO - 错误通信参数测试完成
2025-04-24 20:07:58,707 - error_test - INFO - 测试连接超时...
2025-04-24 20:07:58,707 - modbus_client - INFO - 尝试连接到串口 COM1，波特率 9600
2025-04-24 20:07:58,708 - modbus_client - INFO - 已连接到PLC，端口: COM1
2025-04-24 20:07:58,708 - error_test - INFO - 连接耗时：0.001秒
2025-04-24 20:07:58,708 - error_test - INFO - 连接超时测试完成
2025-04-24 20:07:58,708 - error_test - INFO - 所有连接错误处理测试完成
2025-04-24 20:07:58,708 - error_test - INFO - === 测试重试机制 ===
2025-04-24 20:07:58,708 - modbus_client - INFO - 已更新重试策略: 次数=3, 延迟=0.2秒, 渐进式=False
2025-04-24 20:07:58,708 - modbus_client - INFO - 尝试连接到串口 COM1，波特率 9600
2025-04-24 20:07:58,709 - pymodbus.client.sync - ERROR - could not open port 'COM1': PermissionError(13, '拒绝访问。', None, 5)
2025-04-24 20:07:58,709 - modbus_client - ERROR - 无法连接到PLC，端口: COM1
2025-04-24 20:07:58,709 - error_test - WARNING - 连接失败，无法测试重试机制
2025-04-24 20:07:58,709 - error_test - INFO - === 测试自动重连功能 ===
2025-04-24 20:07:58,709 - modbus_client - INFO - 尝试连接到串口 COM1，波特率 9600
2025-04-24 20:07:58,709 - pymodbus.client.sync - ERROR - could not open port 'COM1': PermissionError(13, '拒绝访问。', None, 5)
2025-04-24 20:07:58,709 - modbus_client - ERROR - 无法连接到PLC，端口: COM1
2025-04-24 20:07:58,709 - error_test - WARNING - 连接失败，无法测试自动重连
2025-04-24 20:07:58,710 - error_test - INFO - === 测试健康检查功能 ===
2025-04-24 20:07:58,710 - modbus_client - INFO - 已更新重试策略: 次数=3, 延迟=0.5秒, 渐进式=True
2025-04-24 20:07:58,710 - plc_communicator - INFO - 创建新ModbusRTUClient实例 - 端口: COM1, 从站地址: 1
2025-04-24 20:07:58,710 - plc_communicator - INFO - 已配置健康检查 - 启用: True, 地址: 0, 间隔: 1秒
2025-04-24 20:07:58,710 - modbus_client - INFO - 尝试连接到串口 COM1，波特率 9600
2025-04-24 20:07:58,710 - pymodbus.client.sync - ERROR - could not open port 'COM1': PermissionError(13, '拒绝访问。', None, 5)
2025-04-24 20:07:58,710 - modbus_client - ERROR - 无法连接到PLC，端口: COM1
2025-04-24 20:07:58,711 - plc_communicator - ERROR - 连接PLC失败
2025-04-24 20:07:58,711 - error_test - WARNING - 连接失败，无法测试健康检查
2025-04-24 20:07:58,711 - error_test - INFO - === 测试数据转换器错误处理 ===
2025-04-24 20:07:58,711 - error_test - INFO - 测试不同字节序...
2025-04-24 20:07:58,711 - error_test - INFO - 字节序 big: 123.456 -> [17142, 59769] -> 123.45600128173828
2025-04-24 20:07:58,711 - error_test - INFO - 字节序 little: 123.456 -> [59769, 17142] -> 123.45600128173828
2025-04-24 20:07:58,711 - error_test - INFO - 字节序 middle_big: 123.456 -> [63042, 31209] -> 123.45600128173828
2025-04-24 20:07:58,711 - error_test - INFO - 字节序 middle_little: 123.456 -> [63042, 31209] -> 123.45600128173828
2025-04-24 20:07:58,712 - error_test - INFO - 测试无效输入...
2025-04-24 20:07:58,712 - data_converter - ERROR - 转换float32需要两个连续寄存器值
2025-04-24 20:07:58,712 - error_test - WARNING - 处理不足两个寄存器时未抛出异常，返回: None
2025-04-24 20:07:58,712 - data_converter - ERROR - 转换float32需要两个连续寄存器值
2025-04-24 20:07:58,712 - error_test - WARNING - 处理空输入时未抛出异常，返回: None
2025-04-24 20:07:58,712 - error_test - INFO - 测试无效字节序...
2025-04-24 20:07:58,712 - data_converter - WARNING - 未知字节序: invalid_order，使用大端字节序
2025-04-24 20:07:58,712 - error_test - INFO - 设置无效字节序被接受，检查是否使用了默认值
2025-04-24 20:07:58,713 - error_test - INFO - 数据转换器测试完成
2025-04-24 20:07:58,713 - error_test - INFO - === 测试并发访问下的错误处理 ===
2025-04-24 20:07:58,713 - modbus_client - INFO - 已更新重试策略: 次数=3, 延迟=0.5秒, 渐进式=True
2025-04-24 20:07:58,713 - plc_communicator - INFO - 创建新ModbusRTUClient实例 - 端口: COM1, 从站地址: 1
2025-04-24 20:07:58,713 - modbus_client - INFO - 已更新重试策略: 次数=2, 延迟=0.5秒, 渐进式=True
2025-04-24 20:07:58,713 - modbus_client - INFO - 已更新重试策略: 次数=2, 延迟=0.1秒, 渐进式=True
2025-04-24 20:07:58,713 - plc_communicator - INFO - 已设置重试策略 - 重试次数: 2, 重试延迟: 0.1秒
2025-04-24 20:07:58,714 - modbus_client - INFO - 尝试连接到串口 COM1，波特率 9600
2025-04-24 20:07:58,714 - pymodbus.client.sync - ERROR - could not open port 'COM1': PermissionError(13, '拒绝访问。', None, 5)
2025-04-24 20:07:58,714 - modbus_client - ERROR - 无法连接到PLC，端口: COM1
2025-04-24 20:07:58,714 - plc_communicator - ERROR - 连接PLC失败
2025-04-24 20:07:58,714 - error_test - WARNING - 连接失败，无法测试并发访问
2025-04-24 20:07:58,714 - error_test - INFO - === 测试PLCCommunicator错误处理 ===
2025-04-24 20:07:58,714 - error_test - INFO - 测试无效连接参数...
2025-04-24 20:07:58,714 - plc_communicator - INFO - 未指定端口，需手动调用connect方法连接
2025-04-24 20:07:58,714 - error_test - INFO - 测试连接超时处理...
2025-04-24 20:07:58,715 - modbus_client - INFO - 已更新重试策略: 次数=3, 延迟=0.5秒, 渐进式=True
2025-04-24 20:07:58,715 - plc_communicator - INFO - 创建新ModbusRTUClient实例 - 端口: NONEXISTENT, 从站地址: 1
2025-04-24 20:07:58,715 - modbus_client - INFO - 尝试连接到串口 NONEXISTENT，波特率 9600
2025-04-24 20:07:58,715 - pymodbus.client.sync - ERROR - could not open port 'NONEXISTENT': FileNotFoundError(2, '系统找不到指定的文件。', None, 2)
2025-04-24 20:07:58,715 - modbus_client - ERROR - 无法连接到PLC，端口: NONEXISTENT
2025-04-24 20:07:58,715 - plc_communicator - ERROR - 连接PLC失败
2025-04-24 20:07:58,715 - error_test - INFO - 测试读取操作错误处理...
2025-04-24 20:07:58,715 - modbus_client - WARNING - 通信客户端未连接，尝试重连...
2025-04-24 20:07:58,715 - modbus_client - INFO - 尝试连接到串口 NONEXISTENT，波特率 9600
2025-04-24 20:07:58,715 - pymodbus.client.sync - ERROR - could not open port 'NONEXISTENT': FileNotFoundError(2, '系统找不到指定的文件。', None, 2)
2025-04-24 20:07:58,716 - modbus_client - ERROR - 无法连接到PLC，端口: NONEXISTENT
2025-04-24 20:07:58,716 - plc_communicator - WARNING - 健康检查失败 - 地址: 0
2025-04-24 20:07:58,716 - plc_communicator - ERROR - 读取重量失败 - 未连接到PLC
2025-04-24 20:07:58,716 - error_test - INFO - 测试写入操作错误处理...
2025-04-24 20:07:58,716 - plc_communicator - WARNING - 与PLC的连接已断开
2025-04-24 20:07:58,716 - modbus_client - INFO - 尝试连接到串口 NONEXISTENT，波特率 9600
2025-04-24 20:07:58,716 - pymodbus.client.sync - ERROR - could not open port 'NONEXISTENT': FileNotFoundError(2, '系统找不到指定的文件。', None, 2)
2025-04-24 20:07:58,716 - modbus_client - ERROR - 无法连接到PLC，端口: NONEXISTENT
2025-04-24 20:07:58,716 - plc_communicator - ERROR - 连接PLC失败
2025-04-24 20:07:58,716 - plc_communicator - ERROR - 写入目标重量失败 - 未连接到PLC
2025-04-24 20:07:58,717 - error_test - INFO - 测试字节序异常处理...
2025-04-24 20:07:58,717 - data_converter - WARNING - 未知字节序: invalid_order，使用大端字节序
2025-04-24 20:07:58,717 - plc_communicator - INFO - 已设置字节序为: invalid_order
2025-04-24 20:07:58,717 - error_test - INFO - 字节序异常处理测试完成
2025-04-24 20:07:58,717 - error_test - INFO - PLCCommunicator错误处理测试完成
2025-04-24 20:07:58,717 - error_test - INFO - === 测试与PLC模拟器的交互 ===
2025-04-24 20:07:58,717 - error_test - ERROR - 测试过程中发生未捕获异常: 'PLCSimulator' object has no attribute 'lock'
2025-04-24 20:07:58,719 - error_test - ERROR - Traceback (most recent call last):
  File "D:\new\test_error_handling.py", line 404, in main
    test_with_simulator()
    ~~~~~~~~~~~~~~~~~~~^^
  File "D:\new\test_error_handling.py", line 301, in test_with_simulator
    simulator = PLCSimulator(slave_id=TEST_UNIT_ID)
  File "D:\new\weighing_system\tests\simulators\plc_simulator.py", line 44, in __init__
    self._init_default_data()
    ~~~~~~~~~~~~~~~~~~~~~~~^^
  File "D:\new\weighing_system\tests\simulators\plc_simulator.py", line 81, in _init_default_data
    self.set_float32(40001, 500.5)
    ~~~~~~~~~~~~~~~~^^^^^^^^^^^^^^
  File "D:\new\weighing_system\tests\simulators\plc_simulator.py", line 266, in set_float32
    return self.write_registers(address, registers)
           ~~~~~~~~~~~~~~~~~~~~^^^^^^^^^^^^^^^^^^^^
  File "D:\new\weighing_system\tests\simulators\plc_simulator.py", line 173, in write_registers
    with self.lock:
         ^^^^^^^^^
AttributeError: 'PLCSimulator' object has no attribute 'lock'

